{
 "cells": [
  {
   "cell_type": "markdown",
   "metadata": {},
   "source": [
    "#### 여기서는 Tutorial에서 배운 개념을 이용하여 간단하게 Network parameter를 분산 환경에서 서로 복사해오는 작업을 해보겠습니다. <br>\n",
    "    1. 각 actor는 network을 가지고 있다. \n",
    "    2. 학습을 하면서 일정 간격으로 actor는 learner의 파라미터를 복제해온다."
   ]
  },
  {
   "cell_type": "code",
   "execution_count": 1,
   "metadata": {},
   "outputs": [],
   "source": [
    "import ray \n",
    "import time \n",
    "import numpy as np \n",
    "\n",
    "import torch\n",
    "import torch.nn as nn\n",
    "import torch.nn.functional as F\n",
    "import torch.optim as optim"
   ]
  },
  {
   "cell_type": "code",
   "execution_count": 2,
   "metadata": {},
   "outputs": [
    {
     "name": "stderr",
     "output_type": "stream",
     "text": [
      "2021-01-23 07:44:53,327\tINFO services.py:1173 -- View the Ray dashboard at \u001b[1m\u001b[32mhttp://127.0.0.1:8265\u001b[39m\u001b[22m\n"
     ]
    },
    {
     "data": {
      "text/plain": [
       "{'node_ip_address': '192.168.0.61',\n",
       " 'raylet_ip_address': '192.168.0.61',\n",
       " 'redis_address': '192.168.0.61:6379',\n",
       " 'object_store_address': '/tmp/ray/session_2021-01-23_07-44-52_876201_94768/sockets/plasma_store',\n",
       " 'raylet_socket_name': '/tmp/ray/session_2021-01-23_07-44-52_876201_94768/sockets/raylet',\n",
       " 'webui_url': '127.0.0.1:8265',\n",
       " 'session_dir': '/tmp/ray/session_2021-01-23_07-44-52_876201_94768',\n",
       " 'metrics_export_port': 37420,\n",
       " 'node_id': 'be3414a09c77cbfb36d74520d7524280deff15dd'}"
      ]
     },
     "execution_count": 2,
     "metadata": {},
     "output_type": "execute_result"
    }
   ],
   "source": [
    "ray.init() "
   ]
  },
  {
   "cell_type": "code",
   "execution_count": 3,
   "metadata": {},
   "outputs": [
    {
     "data": {
      "text/plain": [
       "(tensor([ 0.0674, -0.5022], grad_fn=<AddBackward0>), torch.Size([2]))"
      ]
     },
     "execution_count": 3,
     "metadata": {},
     "output_type": "execute_result"
    }
   ],
   "source": [
    "class QNetwork(nn.Module):\n",
    "    def __init__(self, state_size, action_size, hidden=32):\n",
    "        super(QNetwork, self).__init__()\n",
    "\n",
    "        state_size = state_size[0]\n",
    "        self.fc1 = nn.Linear(state_size, hidden)\n",
    "        self.fc2 = nn.Linear(hidden, action_size)\n",
    "\n",
    "    def forward(self, x):\n",
    "        x = F.relu(self.fc1(x))\n",
    "        x = self.fc2(x)\n",
    "        return x\n",
    "\n",
    "state_size = (4, ) \n",
    "action_size = 2 \n",
    "temp_net = QNetwork(state_size, action_size, 32) \n",
    "test = torch.randn(size=(4,)) \n",
    "temp_net(test), temp_net(test).shape "
   ]
  },
  {
   "cell_type": "code",
   "execution_count": 4,
   "metadata": {},
   "outputs": [],
   "source": [
    "# actor의 역할은 각각 env에서 경험한 것을 buffer에 넘겨주는 역할을 합니다.\n",
    "@ray.remote\n",
    "class Actor:\n",
    "    def __init__(self, \n",
    "                 learner: (\"class: Learner class\"),\n",
    "                 actor_idx: ('int: Actor index'),\n",
    "                 hidden: (\"int: Update frequency of learner's q_behave network\"), \n",
    "                 device: (\"int: Cuda device number\")):\n",
    "\n",
    "        self.learner = learner # ray를 통해 공유하는 learner class입니다.\n",
    "        self.device = device\n",
    "        self.actor_idx = actor_idx\n",
    "\n",
    "        # Network parameters\n",
    "        self.state_dim = (16, )\n",
    "        self.action_dim = 3\n",
    "        self.q_behave = QNetwork(self.state_dim, self.action_dim, hidden).to(self.device)\n",
    "\n",
    "    def explore(self):\n",
    "        print(\"exploration start..\")\n",
    "        while 1:\n",
    "            time.sleep(3)\n",
    "            self.get_weights()\n",
    "            print('updates done.')\n",
    "\n",
    "    def get_weights(self):\n",
    "        weight_copy = self.learner.return_weights.remote()\n",
    "        weight_copy = ray.get(weight_copy)\n",
    "        print(type(weight_copy), self.actor_idx)\n",
    "        self.q_behave.load_state_dict(weight_copy)"
   ]
  },
  {
   "cell_type": "code",
   "execution_count": 5,
   "metadata": {},
   "outputs": [],
   "source": [
    "# 공유 Buffer를 통해 학습을 진행하는 Learner를 정의합니다. \n",
    "# Learner는 buffer에 있는 샘플을 이용하여 network parameter를 업데이트를 하며, agent에게 network weight을 전달합니다.\n",
    "\n",
    "@ray.remote\n",
    "class Learner:\n",
    "    def __init__(self, \n",
    "                 hidden: (\"int: Update frequency of learner's q_behave network\"), \n",
    "                 device: (\"int: Cuda device number\")):\n",
    "        \n",
    "        self.state_dim = (16, )\n",
    "        self.action_dim = 3\n",
    "        self.device = device\n",
    "        \n",
    "        self.q_behave = QNetwork(self.state_dim, self.action_dim, hidden).to(self.device)\n",
    "        self.q_target = QNetwork(self.state_dim, self.action_dim, hidden).to(self.device)\n",
    "        self.q_target.load_state_dict(self.q_behave.state_dict())\n",
    "        self.q_target.eval()\n",
    "\n",
    "    def return_weights(self):\n",
    "        return self.q_target.state_dict() "
   ]
  },
  {
   "cell_type": "code",
   "execution_count": 6,
   "metadata": {},
   "outputs": [
    {
     "name": "stderr",
     "output_type": "stream",
     "text": [
      "\u001b[2m\u001b[36m(pid=94899)\u001b[0m THCudaCheck FAIL file=/opt/conda/conda-bld/pytorch_1579040055865/work/aten/src/THC/THCGeneral.cpp line=50 error=38 : no CUDA-capable device is detected\n",
      "2021-01-23 07:45:00,845\tERROR worker.py:980 -- Possible unhandled error from worker: \u001b[36mray::Learner.__init__()\u001b[39m (pid=94899, ip=192.168.0.61)\n",
      "  File \"python/ray/_raylet.pyx\", line 463, in ray._raylet.execute_task\n",
      "  File \"python/ray/_raylet.pyx\", line 415, in ray._raylet.execute_task.function_executor\n",
      "  File \"<ipython-input-5-7e189b24558d>\", line 14, in __init__\n",
      "  File \"/home/sonic/.conda/envs/RL_Env/lib/python3.7/site-packages/torch/nn/modules/module.py\", line 425, in to\n",
      "    return self._apply(convert)\n",
      "  File \"/home/sonic/.conda/envs/RL_Env/lib/python3.7/site-packages/torch/nn/modules/module.py\", line 201, in _apply\n",
      "    module._apply(fn)\n",
      "  File \"/home/sonic/.conda/envs/RL_Env/lib/python3.7/site-packages/torch/nn/modules/module.py\", line 223, in _apply\n",
      "    param_applied = fn(param)\n",
      "  File \"/home/sonic/.conda/envs/RL_Env/lib/python3.7/site-packages/torch/nn/modules/module.py\", line 423, in convert\n",
      "    return t.to(device, dtype if t.is_floating_point() else None, non_blocking)\n",
      "  File \"/home/sonic/.conda/envs/RL_Env/lib/python3.7/site-packages/torch/cuda/__init__.py\", line 197, in _lazy_init\n",
      "    torch._C._cuda_init()\n",
      "RuntimeError: cuda runtime error (38) : no CUDA-capable device is detected at /opt/conda/conda-bld/pytorch_1579040055865/work/aten/src/THC/THCGeneral.cpp:50\n"
     ]
    }
   ],
   "source": [
    "hidden = 32\n",
    "device = \"cuda:1\" if torch.cuda.is_available() else \"cpu\"\n",
    "# device = \"cpu\"\n",
    "\n",
    "learner = Learner.remote(hidden, device) "
   ]
  },
  {
   "cell_type": "code",
   "execution_count": null,
   "metadata": {},
   "outputs": [],
   "source": [
    "learner"
   ]
  },
  {
   "cell_type": "code",
   "execution_count": 7,
   "metadata": {
    "scrolled": true
   },
   "outputs": [
    {
     "name": "stderr",
     "output_type": "stream",
     "text": [
      "\u001b[2m\u001b[36m(pid=94269)\u001b[0m THCudaCheck FAIL file=/opt/conda/conda-bld/pytorch_1579040055865/work/aten/src/THC/THCGeneral.cpp line=50 error=38 : no CUDA-capable device is detected\n",
      "\u001b[2m\u001b[36m(pid=94272)\u001b[0m THCudaCheck FAIL file=/opt/conda/conda-bld/pytorch_1579040055865/work/aten/src/THC/THCGeneral.cpp line=50 error=38 : no CUDA-capable device is detected\n",
      "\u001b[2m\u001b[36m(pid=94297)\u001b[0m THCudaCheck FAIL file=/opt/conda/conda-bld/pytorch_1579040055865/work/aten/src/THC/THCGeneral.cpp line=50 error=38 : no CUDA-capable device is detected\n",
      "\u001b[2m\u001b[36m(pid=94252)\u001b[0m THCudaCheck FAIL file=/opt/conda/conda-bld/pytorch_1579040055865/work/aten/src/THC/THCGeneral.cpp line=50 error=38 : no CUDA-capable device is detected\n",
      "\u001b[2m\u001b[36m(pid=94295)\u001b[0m THCudaCheck FAIL file=/opt/conda/conda-bld/pytorch_1579040055865/work/aten/src/THC/THCGeneral.cpp line=50 error=38 : no CUDA-capable device is detected\n",
      "\u001b[2m\u001b[36m(pid=94234)\u001b[0m THCudaCheck FAIL file=/opt/conda/conda-bld/pytorch_1579040055865/work/aten/src/THC/THCGeneral.cpp line=50 error=38 : no CUDA-capable device is detected\n",
      "\u001b[2m\u001b[36m(pid=94298)\u001b[0m THCudaCheck FAIL file=/opt/conda/conda-bld/pytorch_1579040055865/work/aten/src/THC/THCGeneral.cpp line=50 error=38 : no CUDA-capable device is detected\n",
      "\u001b[2m\u001b[36m(pid=94258)\u001b[0m THCudaCheck FAIL file=/opt/conda/conda-bld/pytorch_1579040055865/work/aten/src/THC/THCGeneral.cpp line=50 error=38 : no CUDA-capable device is detected\n",
      "\u001b[2m\u001b[36m(pid=94214)\u001b[0m THCudaCheck FAIL file=/opt/conda/conda-bld/pytorch_1579040055865/work/aten/src/THC/THCGeneral.cpp line=50 error=38 : no CUDA-capable device is detected\n",
      "\u001b[2m\u001b[36m(pid=94219)\u001b[0m THCudaCheck FAIL file=/opt/conda/conda-bld/pytorch_1579040055865/work/aten/src/THC/THCGeneral.cpp line=50 error=38 : no CUDA-capable device is detected\n",
      "\u001b[2m\u001b[36m(pid=94245)\u001b[0m THCudaCheck FAIL file=/opt/conda/conda-bld/pytorch_1579040055865/work/aten/src/THC/THCGeneral.cpp line=50 error=38 : no CUDA-capable device is detected\n",
      "\u001b[2m\u001b[36m(pid=94230)\u001b[0m THCudaCheck FAIL file=/opt/conda/conda-bld/pytorch_1579040055865/work/aten/src/THC/THCGeneral.cpp line=50 error=38 : no CUDA-capable device is detected\n",
      "\u001b[2m\u001b[36m(pid=94263)\u001b[0m THCudaCheck FAIL file=/opt/conda/conda-bld/pytorch_1579040055865/work/aten/src/THC/THCGeneral.cpp line=50 error=38 : no CUDA-capable device is detected\n",
      "\u001b[2m\u001b[36m(pid=94227)\u001b[0m THCudaCheck FAIL file=/opt/conda/conda-bld/pytorch_1579040055865/work/aten/src/THC/THCGeneral.cpp line=50 error=38 : no CUDA-capable device is detected\n",
      "\u001b[2m\u001b[36m(pid=94261)\u001b[0m THCudaCheck FAIL file=/opt/conda/conda-bld/pytorch_1579040055865/work/aten/src/THC/THCGeneral.cpp line=50 error=38 : no CUDA-capable device is detected\n",
      "\u001b[2m\u001b[36m(pid=94296)\u001b[0m THCudaCheck FAIL file=/opt/conda/conda-bld/pytorch_1579040055865/work/aten/src/THC/THCGeneral.cpp line=50 error=38 : no CUDA-capable device is detected\n",
      "\u001b[2m\u001b[36m(pid=94220)\u001b[0m THCudaCheck FAIL file=/opt/conda/conda-bld/pytorch_1579040055865/work/aten/src/THC/THCGeneral.cpp line=50 error=38 : no CUDA-capable device is detected\n",
      "2021-01-23 07:44:08,701\tERROR worker.py:980 -- Possible unhandled error from worker: \u001b[36mray::Learner.__init__()\u001b[39m (pid=94297, ip=192.168.0.61)\n",
      "  File \"python/ray/_raylet.pyx\", line 463, in ray._raylet.execute_task\n",
      "  File \"python/ray/_raylet.pyx\", line 415, in ray._raylet.execute_task.function_executor\n",
      "  File \"<ipython-input-5-7e189b24558d>\", line 14, in __init__\n",
      "  File \"/home/sonic/.conda/envs/RL_Env/lib/python3.7/site-packages/torch/nn/modules/module.py\", line 425, in to\n",
      "    return self._apply(convert)\n",
      "  File \"/home/sonic/.conda/envs/RL_Env/lib/python3.7/site-packages/torch/nn/modules/module.py\", line 201, in _apply\n",
      "    module._apply(fn)\n",
      "  File \"/home/sonic/.conda/envs/RL_Env/lib/python3.7/site-packages/torch/nn/modules/module.py\", line 223, in _apply\n",
      "    param_applied = fn(param)\n",
      "  File \"/home/sonic/.conda/envs/RL_Env/lib/python3.7/site-packages/torch/nn/modules/module.py\", line 423, in convert\n",
      "    return t.to(device, dtype if t.is_floating_point() else None, non_blocking)\n",
      "  File \"/home/sonic/.conda/envs/RL_Env/lib/python3.7/site-packages/torch/cuda/__init__.py\", line 197, in _lazy_init\n",
      "    torch._C._cuda_init()\n",
      "RuntimeError: cuda runtime error (38) : no CUDA-capable device is detected at /opt/conda/conda-bld/pytorch_1579040055865/work/aten/src/THC/THCGeneral.cpp:50\n",
      "2021-01-23 07:44:08,703\tERROR worker.py:980 -- Possible unhandled error from worker: \u001b[36mray::Actor.__init__()\u001b[39m (pid=94269, ip=192.168.0.61)\n",
      "  File \"python/ray/_raylet.pyx\", line 463, in ray._raylet.execute_task\n",
      "  File \"python/ray/_raylet.pyx\", line 415, in ray._raylet.execute_task.function_executor\n",
      "  File \"<ipython-input-4-bb353c57f130>\", line 17, in __init__\n",
      "  File \"/home/sonic/.conda/envs/RL_Env/lib/python3.7/site-packages/torch/nn/modules/module.py\", line 425, in to\n",
      "    return self._apply(convert)\n",
      "  File \"/home/sonic/.conda/envs/RL_Env/lib/python3.7/site-packages/torch/nn/modules/module.py\", line 201, in _apply\n",
      "    module._apply(fn)\n",
      "  File \"/home/sonic/.conda/envs/RL_Env/lib/python3.7/site-packages/torch/nn/modules/module.py\", line 223, in _apply\n",
      "    param_applied = fn(param)\n",
      "  File \"/home/sonic/.conda/envs/RL_Env/lib/python3.7/site-packages/torch/nn/modules/module.py\", line 423, in convert\n",
      "    return t.to(device, dtype if t.is_floating_point() else None, non_blocking)\n",
      "  File \"/home/sonic/.conda/envs/RL_Env/lib/python3.7/site-packages/torch/cuda/__init__.py\", line 197, in _lazy_init\n",
      "    torch._C._cuda_init()\n",
      "RuntimeError: cuda runtime error (38) : no CUDA-capable device is detected at /opt/conda/conda-bld/pytorch_1579040055865/work/aten/src/THC/THCGeneral.cpp:50\n",
      "2021-01-23 07:44:08,705\tERROR worker.py:980 -- Possible unhandled error from worker: \u001b[36mray::Actor.explore()\u001b[39m (pid=94269, ip=192.168.0.61)\n",
      "  File \"python/ray/_raylet.pyx\", line 422, in ray._raylet.execute_task\n",
      "  File \"python/ray/_raylet.pyx\", line 456, in ray._raylet.execute_task\n",
      "  File \"python/ray/_raylet.pyx\", line 459, in ray._raylet.execute_task\n",
      "  File \"python/ray/_raylet.pyx\", line 463, in ray._raylet.execute_task\n",
      "  File \"python/ray/_raylet.pyx\", line 415, in ray._raylet.execute_task.function_executor\n",
      "  File \"<ipython-input-4-bb353c57f130>\", line 17, in __init__\n",
      "  File \"/home/sonic/.conda/envs/RL_Env/lib/python3.7/site-packages/torch/nn/modules/module.py\", line 425, in to\n",
      "    return self._apply(convert)\n",
      "  File \"/home/sonic/.conda/envs/RL_Env/lib/python3.7/site-packages/torch/nn/modules/module.py\", line 201, in _apply\n",
      "    module._apply(fn)\n",
      "  File \"/home/sonic/.conda/envs/RL_Env/lib/python3.7/site-packages/torch/nn/modules/module.py\", line 223, in _apply\n",
      "    param_applied = fn(param)\n",
      "  File \"/home/sonic/.conda/envs/RL_Env/lib/python3.7/site-packages/torch/nn/modules/module.py\", line 423, in convert\n",
      "    return t.to(device, dtype if t.is_floating_point() else None, non_blocking)\n",
      "  File \"/home/sonic/.conda/envs/RL_Env/lib/python3.7/site-packages/torch/cuda/__init__.py\", line 197, in _lazy_init\n",
      "    torch._C._cuda_init()\n",
      "RuntimeError: cuda runtime error (38) : no CUDA-capable device is detected at /opt/conda/conda-bld/pytorch_1579040055865/work/aten/src/THC/THCGeneral.cpp:50\n",
      "2021-01-23 07:44:08,707\tERROR worker.py:980 -- Possible unhandled error from worker: \u001b[36mray::Actor.__init__()\u001b[39m (pid=94272, ip=192.168.0.61)\n",
      "  File \"python/ray/_raylet.pyx\", line 463, in ray._raylet.execute_task\n",
      "  File \"python/ray/_raylet.pyx\", line 415, in ray._raylet.execute_task.function_executor\n",
      "  File \"<ipython-input-4-bb353c57f130>\", line 17, in __init__\n",
      "  File \"/home/sonic/.conda/envs/RL_Env/lib/python3.7/site-packages/torch/nn/modules/module.py\", line 425, in to\n",
      "    return self._apply(convert)\n",
      "  File \"/home/sonic/.conda/envs/RL_Env/lib/python3.7/site-packages/torch/nn/modules/module.py\", line 201, in _apply\n",
      "    module._apply(fn)\n",
      "  File \"/home/sonic/.conda/envs/RL_Env/lib/python3.7/site-packages/torch/nn/modules/module.py\", line 223, in _apply\n",
      "    param_applied = fn(param)\n",
      "  File \"/home/sonic/.conda/envs/RL_Env/lib/python3.7/site-packages/torch/nn/modules/module.py\", line 423, in convert\n",
      "    return t.to(device, dtype if t.is_floating_point() else None, non_blocking)\n",
      "  File \"/home/sonic/.conda/envs/RL_Env/lib/python3.7/site-packages/torch/cuda/__init__.py\", line 197, in _lazy_init\n",
      "    torch._C._cuda_init()\n",
      "RuntimeError: cuda runtime error (38) : no CUDA-capable device is detected at /opt/conda/conda-bld/pytorch_1579040055865/work/aten/src/THC/THCGeneral.cpp:50\n"
     ]
    },
    {
     "name": "stderr",
     "output_type": "stream",
     "text": [
      "2021-01-23 07:44:09,708\tERROR worker.py:980 -- Possible unhandled error from worker: \u001b[36mray::Actor.explore()\u001b[39m (pid=94272, ip=192.168.0.61)\n",
      "  File \"python/ray/_raylet.pyx\", line 422, in ray._raylet.execute_task\n",
      "  File \"python/ray/_raylet.pyx\", line 456, in ray._raylet.execute_task\n",
      "  File \"python/ray/_raylet.pyx\", line 459, in ray._raylet.execute_task\n",
      "  File \"python/ray/_raylet.pyx\", line 463, in ray._raylet.execute_task\n",
      "  File \"python/ray/_raylet.pyx\", line 415, in ray._raylet.execute_task.function_executor\n",
      "  File \"<ipython-input-4-bb353c57f130>\", line 17, in __init__\n",
      "  File \"/home/sonic/.conda/envs/RL_Env/lib/python3.7/site-packages/torch/nn/modules/module.py\", line 425, in to\n",
      "    return self._apply(convert)\n",
      "  File \"/home/sonic/.conda/envs/RL_Env/lib/python3.7/site-packages/torch/nn/modules/module.py\", line 201, in _apply\n",
      "    module._apply(fn)\n",
      "  File \"/home/sonic/.conda/envs/RL_Env/lib/python3.7/site-packages/torch/nn/modules/module.py\", line 223, in _apply\n",
      "    param_applied = fn(param)\n",
      "  File \"/home/sonic/.conda/envs/RL_Env/lib/python3.7/site-packages/torch/nn/modules/module.py\", line 423, in convert\n",
      "    return t.to(device, dtype if t.is_floating_point() else None, non_blocking)\n",
      "  File \"/home/sonic/.conda/envs/RL_Env/lib/python3.7/site-packages/torch/cuda/__init__.py\", line 197, in _lazy_init\n",
      "    torch._C._cuda_init()\n",
      "RuntimeError: cuda runtime error (38) : no CUDA-capable device is detected at /opt/conda/conda-bld/pytorch_1579040055865/work/aten/src/THC/THCGeneral.cpp:50\n",
      "2021-01-23 07:44:09,710\tERROR worker.py:980 -- Possible unhandled error from worker: \u001b[36mray::Actor.__init__()\u001b[39m (pid=94252, ip=192.168.0.61)\n",
      "  File \"python/ray/_raylet.pyx\", line 463, in ray._raylet.execute_task\n",
      "  File \"python/ray/_raylet.pyx\", line 415, in ray._raylet.execute_task.function_executor\n",
      "  File \"<ipython-input-4-bb353c57f130>\", line 17, in __init__\n",
      "  File \"/home/sonic/.conda/envs/RL_Env/lib/python3.7/site-packages/torch/nn/modules/module.py\", line 425, in to\n",
      "    return self._apply(convert)\n",
      "  File \"/home/sonic/.conda/envs/RL_Env/lib/python3.7/site-packages/torch/nn/modules/module.py\", line 201, in _apply\n",
      "    module._apply(fn)\n",
      "  File \"/home/sonic/.conda/envs/RL_Env/lib/python3.7/site-packages/torch/nn/modules/module.py\", line 223, in _apply\n",
      "    param_applied = fn(param)\n",
      "  File \"/home/sonic/.conda/envs/RL_Env/lib/python3.7/site-packages/torch/nn/modules/module.py\", line 423, in convert\n",
      "    return t.to(device, dtype if t.is_floating_point() else None, non_blocking)\n",
      "  File \"/home/sonic/.conda/envs/RL_Env/lib/python3.7/site-packages/torch/cuda/__init__.py\", line 197, in _lazy_init\n",
      "    torch._C._cuda_init()\n",
      "RuntimeError: cuda runtime error (38) : no CUDA-capable device is detected at /opt/conda/conda-bld/pytorch_1579040055865/work/aten/src/THC/THCGeneral.cpp:50\n",
      "2021-01-23 07:44:09,713\tERROR worker.py:980 -- Possible unhandled error from worker: \u001b[36mray::Actor.explore()\u001b[39m (pid=94252, ip=192.168.0.61)\n",
      "  File \"python/ray/_raylet.pyx\", line 422, in ray._raylet.execute_task\n",
      "  File \"python/ray/_raylet.pyx\", line 456, in ray._raylet.execute_task\n",
      "  File \"python/ray/_raylet.pyx\", line 459, in ray._raylet.execute_task\n",
      "  File \"python/ray/_raylet.pyx\", line 463, in ray._raylet.execute_task\n",
      "  File \"python/ray/_raylet.pyx\", line 415, in ray._raylet.execute_task.function_executor\n",
      "  File \"<ipython-input-4-bb353c57f130>\", line 17, in __init__\n",
      "  File \"/home/sonic/.conda/envs/RL_Env/lib/python3.7/site-packages/torch/nn/modules/module.py\", line 425, in to\n",
      "    return self._apply(convert)\n",
      "  File \"/home/sonic/.conda/envs/RL_Env/lib/python3.7/site-packages/torch/nn/modules/module.py\", line 201, in _apply\n",
      "    module._apply(fn)\n",
      "  File \"/home/sonic/.conda/envs/RL_Env/lib/python3.7/site-packages/torch/nn/modules/module.py\", line 223, in _apply\n",
      "    param_applied = fn(param)\n",
      "  File \"/home/sonic/.conda/envs/RL_Env/lib/python3.7/site-packages/torch/nn/modules/module.py\", line 423, in convert\n",
      "    return t.to(device, dtype if t.is_floating_point() else None, non_blocking)\n",
      "  File \"/home/sonic/.conda/envs/RL_Env/lib/python3.7/site-packages/torch/cuda/__init__.py\", line 197, in _lazy_init\n",
      "    torch._C._cuda_init()\n",
      "RuntimeError: cuda runtime error (38) : no CUDA-capable device is detected at /opt/conda/conda-bld/pytorch_1579040055865/work/aten/src/THC/THCGeneral.cpp:50\n",
      "2021-01-23 07:44:09,714\tERROR worker.py:980 -- Possible unhandled error from worker: \u001b[36mray::Actor.__init__()\u001b[39m (pid=94234, ip=192.168.0.61)\n",
      "  File \"python/ray/_raylet.pyx\", line 463, in ray._raylet.execute_task\n",
      "  File \"python/ray/_raylet.pyx\", line 415, in ray._raylet.execute_task.function_executor\n",
      "  File \"<ipython-input-4-bb353c57f130>\", line 17, in __init__\n",
      "  File \"/home/sonic/.conda/envs/RL_Env/lib/python3.7/site-packages/torch/nn/modules/module.py\", line 425, in to\n",
      "    return self._apply(convert)\n",
      "  File \"/home/sonic/.conda/envs/RL_Env/lib/python3.7/site-packages/torch/nn/modules/module.py\", line 201, in _apply\n",
      "    module._apply(fn)\n",
      "  File \"/home/sonic/.conda/envs/RL_Env/lib/python3.7/site-packages/torch/nn/modules/module.py\", line 223, in _apply\n",
      "    param_applied = fn(param)\n",
      "  File \"/home/sonic/.conda/envs/RL_Env/lib/python3.7/site-packages/torch/nn/modules/module.py\", line 423, in convert\n",
      "    return t.to(device, dtype if t.is_floating_point() else None, non_blocking)\n",
      "  File \"/home/sonic/.conda/envs/RL_Env/lib/python3.7/site-packages/torch/cuda/__init__.py\", line 197, in _lazy_init\n",
      "    torch._C._cuda_init()\n",
      "RuntimeError: cuda runtime error (38) : no CUDA-capable device is detected at /opt/conda/conda-bld/pytorch_1579040055865/work/aten/src/THC/THCGeneral.cpp:50\n",
      "2021-01-23 07:44:09,716\tERROR worker.py:980 -- Possible unhandled error from worker: \u001b[36mray::Actor.__init__()\u001b[39m (pid=94295, ip=192.168.0.61)\n",
      "  File \"python/ray/_raylet.pyx\", line 463, in ray._raylet.execute_task\n",
      "  File \"python/ray/_raylet.pyx\", line 415, in ray._raylet.execute_task.function_executor\n",
      "  File \"<ipython-input-4-bb353c57f130>\", line 17, in __init__\n",
      "  File \"/home/sonic/.conda/envs/RL_Env/lib/python3.7/site-packages/torch/nn/modules/module.py\", line 425, in to\n",
      "    return self._apply(convert)\n",
      "  File \"/home/sonic/.conda/envs/RL_Env/lib/python3.7/site-packages/torch/nn/modules/module.py\", line 201, in _apply\n",
      "    module._apply(fn)\n",
      "  File \"/home/sonic/.conda/envs/RL_Env/lib/python3.7/site-packages/torch/nn/modules/module.py\", line 223, in _apply\n",
      "    param_applied = fn(param)\n",
      "  File \"/home/sonic/.conda/envs/RL_Env/lib/python3.7/site-packages/torch/nn/modules/module.py\", line 423, in convert\n",
      "    return t.to(device, dtype if t.is_floating_point() else None, non_blocking)\n",
      "  File \"/home/sonic/.conda/envs/RL_Env/lib/python3.7/site-packages/torch/cuda/__init__.py\", line 197, in _lazy_init\n",
      "    torch._C._cuda_init()\n",
      "RuntimeError: cuda runtime error (38) : no CUDA-capable device is detected at /opt/conda/conda-bld/pytorch_1579040055865/work/aten/src/THC/THCGeneral.cpp:50\n",
      "2021-01-23 07:44:09,718\tERROR worker.py:980 -- Possible unhandled error from worker: \u001b[36mray::Actor.explore()\u001b[39m (pid=94234, ip=192.168.0.61)\n",
      "  File \"python/ray/_raylet.pyx\", line 422, in ray._raylet.execute_task\n",
      "  File \"python/ray/_raylet.pyx\", line 456, in ray._raylet.execute_task\n",
      "  File \"python/ray/_raylet.pyx\", line 459, in ray._raylet.execute_task\n",
      "  File \"python/ray/_raylet.pyx\", line 463, in ray._raylet.execute_task\n",
      "  File \"python/ray/_raylet.pyx\", line 415, in ray._raylet.execute_task.function_executor\n",
      "  File \"<ipython-input-4-bb353c57f130>\", line 17, in __init__\n",
      "  File \"/home/sonic/.conda/envs/RL_Env/lib/python3.7/site-packages/torch/nn/modules/module.py\", line 425, in to\n",
      "    return self._apply(convert)\n",
      "  File \"/home/sonic/.conda/envs/RL_Env/lib/python3.7/site-packages/torch/nn/modules/module.py\", line 201, in _apply\n",
      "    module._apply(fn)\n",
      "  File \"/home/sonic/.conda/envs/RL_Env/lib/python3.7/site-packages/torch/nn/modules/module.py\", line 223, in _apply\n",
      "    param_applied = fn(param)\n",
      "  File \"/home/sonic/.conda/envs/RL_Env/lib/python3.7/site-packages/torch/nn/modules/module.py\", line 423, in convert\n",
      "    return t.to(device, dtype if t.is_floating_point() else None, non_blocking)\n",
      "  File \"/home/sonic/.conda/envs/RL_Env/lib/python3.7/site-packages/torch/cuda/__init__.py\", line 197, in _lazy_init\n",
      "    torch._C._cuda_init()\n",
      "RuntimeError: cuda runtime error (38) : no CUDA-capable device is detected at /opt/conda/conda-bld/pytorch_1579040055865/work/aten/src/THC/THCGeneral.cpp:50\n"
     ]
    },
    {
     "name": "stderr",
     "output_type": "stream",
     "text": [
      "2021-01-23 07:44:09,719\tERROR worker.py:980 -- Possible unhandled error from worker: \u001b[36mray::Actor.explore()\u001b[39m (pid=94295, ip=192.168.0.61)\n",
      "  File \"python/ray/_raylet.pyx\", line 422, in ray._raylet.execute_task\n",
      "  File \"python/ray/_raylet.pyx\", line 456, in ray._raylet.execute_task\n",
      "  File \"python/ray/_raylet.pyx\", line 459, in ray._raylet.execute_task\n",
      "  File \"python/ray/_raylet.pyx\", line 463, in ray._raylet.execute_task\n",
      "  File \"python/ray/_raylet.pyx\", line 415, in ray._raylet.execute_task.function_executor\n",
      "  File \"<ipython-input-4-bb353c57f130>\", line 17, in __init__\n",
      "  File \"/home/sonic/.conda/envs/RL_Env/lib/python3.7/site-packages/torch/nn/modules/module.py\", line 425, in to\n",
      "    return self._apply(convert)\n",
      "  File \"/home/sonic/.conda/envs/RL_Env/lib/python3.7/site-packages/torch/nn/modules/module.py\", line 201, in _apply\n",
      "    module._apply(fn)\n",
      "  File \"/home/sonic/.conda/envs/RL_Env/lib/python3.7/site-packages/torch/nn/modules/module.py\", line 223, in _apply\n",
      "    param_applied = fn(param)\n",
      "  File \"/home/sonic/.conda/envs/RL_Env/lib/python3.7/site-packages/torch/nn/modules/module.py\", line 423, in convert\n",
      "    return t.to(device, dtype if t.is_floating_point() else None, non_blocking)\n",
      "  File \"/home/sonic/.conda/envs/RL_Env/lib/python3.7/site-packages/torch/cuda/__init__.py\", line 197, in _lazy_init\n",
      "    torch._C._cuda_init()\n",
      "RuntimeError: cuda runtime error (38) : no CUDA-capable device is detected at /opt/conda/conda-bld/pytorch_1579040055865/work/aten/src/THC/THCGeneral.cpp:50\n",
      "2021-01-23 07:44:09,720\tERROR worker.py:980 -- Possible unhandled error from worker: \u001b[36mray::Actor.__init__()\u001b[39m (pid=94298, ip=192.168.0.61)\n",
      "  File \"python/ray/_raylet.pyx\", line 463, in ray._raylet.execute_task\n",
      "  File \"python/ray/_raylet.pyx\", line 415, in ray._raylet.execute_task.function_executor\n",
      "  File \"<ipython-input-4-bb353c57f130>\", line 17, in __init__\n",
      "  File \"/home/sonic/.conda/envs/RL_Env/lib/python3.7/site-packages/torch/nn/modules/module.py\", line 425, in to\n",
      "    return self._apply(convert)\n",
      "  File \"/home/sonic/.conda/envs/RL_Env/lib/python3.7/site-packages/torch/nn/modules/module.py\", line 201, in _apply\n",
      "    module._apply(fn)\n",
      "  File \"/home/sonic/.conda/envs/RL_Env/lib/python3.7/site-packages/torch/nn/modules/module.py\", line 223, in _apply\n",
      "    param_applied = fn(param)\n",
      "  File \"/home/sonic/.conda/envs/RL_Env/lib/python3.7/site-packages/torch/nn/modules/module.py\", line 423, in convert\n",
      "    return t.to(device, dtype if t.is_floating_point() else None, non_blocking)\n",
      "  File \"/home/sonic/.conda/envs/RL_Env/lib/python3.7/site-packages/torch/cuda/__init__.py\", line 197, in _lazy_init\n",
      "    torch._C._cuda_init()\n",
      "RuntimeError: cuda runtime error (38) : no CUDA-capable device is detected at /opt/conda/conda-bld/pytorch_1579040055865/work/aten/src/THC/THCGeneral.cpp:50\n",
      "2021-01-23 07:44:09,722\tERROR worker.py:980 -- Possible unhandled error from worker: \u001b[36mray::Actor.explore()\u001b[39m (pid=94298, ip=192.168.0.61)\n",
      "  File \"python/ray/_raylet.pyx\", line 422, in ray._raylet.execute_task\n",
      "  File \"python/ray/_raylet.pyx\", line 456, in ray._raylet.execute_task\n",
      "  File \"python/ray/_raylet.pyx\", line 459, in ray._raylet.execute_task\n",
      "  File \"python/ray/_raylet.pyx\", line 463, in ray._raylet.execute_task\n",
      "  File \"python/ray/_raylet.pyx\", line 415, in ray._raylet.execute_task.function_executor\n",
      "  File \"<ipython-input-4-bb353c57f130>\", line 17, in __init__\n",
      "  File \"/home/sonic/.conda/envs/RL_Env/lib/python3.7/site-packages/torch/nn/modules/module.py\", line 425, in to\n",
      "    return self._apply(convert)\n",
      "  File \"/home/sonic/.conda/envs/RL_Env/lib/python3.7/site-packages/torch/nn/modules/module.py\", line 201, in _apply\n",
      "    module._apply(fn)\n",
      "  File \"/home/sonic/.conda/envs/RL_Env/lib/python3.7/site-packages/torch/nn/modules/module.py\", line 223, in _apply\n",
      "    param_applied = fn(param)\n",
      "  File \"/home/sonic/.conda/envs/RL_Env/lib/python3.7/site-packages/torch/nn/modules/module.py\", line 423, in convert\n",
      "    return t.to(device, dtype if t.is_floating_point() else None, non_blocking)\n",
      "  File \"/home/sonic/.conda/envs/RL_Env/lib/python3.7/site-packages/torch/cuda/__init__.py\", line 197, in _lazy_init\n",
      "    torch._C._cuda_init()\n",
      "RuntimeError: cuda runtime error (38) : no CUDA-capable device is detected at /opt/conda/conda-bld/pytorch_1579040055865/work/aten/src/THC/THCGeneral.cpp:50\n",
      "2021-01-23 07:44:09,725\tERROR worker.py:980 -- Possible unhandled error from worker: \u001b[36mray::Actor.__init__()\u001b[39m (pid=94258, ip=192.168.0.61)\n",
      "  File \"python/ray/_raylet.pyx\", line 463, in ray._raylet.execute_task\n",
      "  File \"python/ray/_raylet.pyx\", line 415, in ray._raylet.execute_task.function_executor\n",
      "  File \"<ipython-input-4-bb353c57f130>\", line 17, in __init__\n",
      "  File \"/home/sonic/.conda/envs/RL_Env/lib/python3.7/site-packages/torch/nn/modules/module.py\", line 425, in to\n",
      "    return self._apply(convert)\n",
      "  File \"/home/sonic/.conda/envs/RL_Env/lib/python3.7/site-packages/torch/nn/modules/module.py\", line 201, in _apply\n",
      "    module._apply(fn)\n",
      "  File \"/home/sonic/.conda/envs/RL_Env/lib/python3.7/site-packages/torch/nn/modules/module.py\", line 223, in _apply\n",
      "    param_applied = fn(param)\n",
      "  File \"/home/sonic/.conda/envs/RL_Env/lib/python3.7/site-packages/torch/nn/modules/module.py\", line 423, in convert\n",
      "    return t.to(device, dtype if t.is_floating_point() else None, non_blocking)\n",
      "  File \"/home/sonic/.conda/envs/RL_Env/lib/python3.7/site-packages/torch/cuda/__init__.py\", line 197, in _lazy_init\n",
      "    torch._C._cuda_init()\n",
      "RuntimeError: cuda runtime error (38) : no CUDA-capable device is detected at /opt/conda/conda-bld/pytorch_1579040055865/work/aten/src/THC/THCGeneral.cpp:50\n",
      "2021-01-23 07:44:09,727\tERROR worker.py:980 -- Possible unhandled error from worker: \u001b[36mray::Actor.explore()\u001b[39m (pid=94258, ip=192.168.0.61)\n",
      "  File \"python/ray/_raylet.pyx\", line 422, in ray._raylet.execute_task\n",
      "  File \"python/ray/_raylet.pyx\", line 456, in ray._raylet.execute_task\n",
      "  File \"python/ray/_raylet.pyx\", line 459, in ray._raylet.execute_task\n",
      "  File \"python/ray/_raylet.pyx\", line 463, in ray._raylet.execute_task\n",
      "  File \"python/ray/_raylet.pyx\", line 415, in ray._raylet.execute_task.function_executor\n",
      "  File \"<ipython-input-4-bb353c57f130>\", line 17, in __init__\n",
      "  File \"/home/sonic/.conda/envs/RL_Env/lib/python3.7/site-packages/torch/nn/modules/module.py\", line 425, in to\n",
      "    return self._apply(convert)\n",
      "  File \"/home/sonic/.conda/envs/RL_Env/lib/python3.7/site-packages/torch/nn/modules/module.py\", line 201, in _apply\n",
      "    module._apply(fn)\n",
      "  File \"/home/sonic/.conda/envs/RL_Env/lib/python3.7/site-packages/torch/nn/modules/module.py\", line 223, in _apply\n",
      "    param_applied = fn(param)\n",
      "  File \"/home/sonic/.conda/envs/RL_Env/lib/python3.7/site-packages/torch/nn/modules/module.py\", line 423, in convert\n",
      "    return t.to(device, dtype if t.is_floating_point() else None, non_blocking)\n",
      "  File \"/home/sonic/.conda/envs/RL_Env/lib/python3.7/site-packages/torch/cuda/__init__.py\", line 197, in _lazy_init\n",
      "    torch._C._cuda_init()\n",
      "RuntimeError: cuda runtime error (38) : no CUDA-capable device is detected at /opt/conda/conda-bld/pytorch_1579040055865/work/aten/src/THC/THCGeneral.cpp:50\n",
      "2021-01-23 07:44:09,728\tERROR worker.py:980 -- Possible unhandled error from worker: \u001b[36mray::Actor.__init__()\u001b[39m (pid=94220, ip=192.168.0.61)\n",
      "  File \"python/ray/_raylet.pyx\", line 463, in ray._raylet.execute_task\n",
      "  File \"python/ray/_raylet.pyx\", line 415, in ray._raylet.execute_task.function_executor\n",
      "  File \"<ipython-input-4-bb353c57f130>\", line 17, in __init__\n",
      "  File \"/home/sonic/.conda/envs/RL_Env/lib/python3.7/site-packages/torch/nn/modules/module.py\", line 425, in to\n",
      "    return self._apply(convert)\n",
      "  File \"/home/sonic/.conda/envs/RL_Env/lib/python3.7/site-packages/torch/nn/modules/module.py\", line 201, in _apply\n",
      "    module._apply(fn)\n",
      "  File \"/home/sonic/.conda/envs/RL_Env/lib/python3.7/site-packages/torch/nn/modules/module.py\", line 223, in _apply\n",
      "    param_applied = fn(param)\n",
      "  File \"/home/sonic/.conda/envs/RL_Env/lib/python3.7/site-packages/torch/nn/modules/module.py\", line 423, in convert\n",
      "    return t.to(device, dtype if t.is_floating_point() else None, non_blocking)\n",
      "  File \"/home/sonic/.conda/envs/RL_Env/lib/python3.7/site-packages/torch/cuda/__init__.py\", line 197, in _lazy_init\n",
      "    torch._C._cuda_init()\n",
      "RuntimeError: cuda runtime error (38) : no CUDA-capable device is detected at /opt/conda/conda-bld/pytorch_1579040055865/work/aten/src/THC/THCGeneral.cpp:50\n"
     ]
    },
    {
     "name": "stderr",
     "output_type": "stream",
     "text": [
      "2021-01-23 07:44:09,729\tERROR worker.py:980 -- Possible unhandled error from worker: \u001b[36mray::Actor.explore()\u001b[39m (pid=94220, ip=192.168.0.61)\n",
      "  File \"python/ray/_raylet.pyx\", line 422, in ray._raylet.execute_task\n",
      "  File \"python/ray/_raylet.pyx\", line 456, in ray._raylet.execute_task\n",
      "  File \"python/ray/_raylet.pyx\", line 459, in ray._raylet.execute_task\n",
      "  File \"python/ray/_raylet.pyx\", line 463, in ray._raylet.execute_task\n",
      "  File \"python/ray/_raylet.pyx\", line 415, in ray._raylet.execute_task.function_executor\n",
      "  File \"<ipython-input-4-bb353c57f130>\", line 17, in __init__\n",
      "  File \"/home/sonic/.conda/envs/RL_Env/lib/python3.7/site-packages/torch/nn/modules/module.py\", line 425, in to\n",
      "    return self._apply(convert)\n",
      "  File \"/home/sonic/.conda/envs/RL_Env/lib/python3.7/site-packages/torch/nn/modules/module.py\", line 201, in _apply\n",
      "    module._apply(fn)\n",
      "  File \"/home/sonic/.conda/envs/RL_Env/lib/python3.7/site-packages/torch/nn/modules/module.py\", line 223, in _apply\n",
      "    param_applied = fn(param)\n",
      "  File \"/home/sonic/.conda/envs/RL_Env/lib/python3.7/site-packages/torch/nn/modules/module.py\", line 423, in convert\n",
      "    return t.to(device, dtype if t.is_floating_point() else None, non_blocking)\n",
      "  File \"/home/sonic/.conda/envs/RL_Env/lib/python3.7/site-packages/torch/cuda/__init__.py\", line 197, in _lazy_init\n",
      "    torch._C._cuda_init()\n",
      "RuntimeError: cuda runtime error (38) : no CUDA-capable device is detected at /opt/conda/conda-bld/pytorch_1579040055865/work/aten/src/THC/THCGeneral.cpp:50\n",
      "2021-01-23 07:44:09,730\tERROR worker.py:980 -- Possible unhandled error from worker: \u001b[36mray::Actor.__init__()\u001b[39m (pid=94245, ip=192.168.0.61)\n",
      "  File \"python/ray/_raylet.pyx\", line 463, in ray._raylet.execute_task\n",
      "  File \"python/ray/_raylet.pyx\", line 415, in ray._raylet.execute_task.function_executor\n",
      "  File \"<ipython-input-4-bb353c57f130>\", line 17, in __init__\n",
      "  File \"/home/sonic/.conda/envs/RL_Env/lib/python3.7/site-packages/torch/nn/modules/module.py\", line 425, in to\n",
      "    return self._apply(convert)\n",
      "  File \"/home/sonic/.conda/envs/RL_Env/lib/python3.7/site-packages/torch/nn/modules/module.py\", line 201, in _apply\n",
      "    module._apply(fn)\n",
      "  File \"/home/sonic/.conda/envs/RL_Env/lib/python3.7/site-packages/torch/nn/modules/module.py\", line 223, in _apply\n",
      "    param_applied = fn(param)\n",
      "  File \"/home/sonic/.conda/envs/RL_Env/lib/python3.7/site-packages/torch/nn/modules/module.py\", line 423, in convert\n",
      "    return t.to(device, dtype if t.is_floating_point() else None, non_blocking)\n",
      "  File \"/home/sonic/.conda/envs/RL_Env/lib/python3.7/site-packages/torch/cuda/__init__.py\", line 197, in _lazy_init\n",
      "    torch._C._cuda_init()\n",
      "RuntimeError: cuda runtime error (38) : no CUDA-capable device is detected at /opt/conda/conda-bld/pytorch_1579040055865/work/aten/src/THC/THCGeneral.cpp:50\n",
      "2021-01-23 07:44:09,732\tERROR worker.py:980 -- Possible unhandled error from worker: \u001b[36mray::Actor.__init__()\u001b[39m (pid=94263, ip=192.168.0.61)\n",
      "  File \"python/ray/_raylet.pyx\", line 463, in ray._raylet.execute_task\n",
      "  File \"python/ray/_raylet.pyx\", line 415, in ray._raylet.execute_task.function_executor\n",
      "  File \"<ipython-input-4-bb353c57f130>\", line 17, in __init__\n",
      "  File \"/home/sonic/.conda/envs/RL_Env/lib/python3.7/site-packages/torch/nn/modules/module.py\", line 425, in to\n",
      "    return self._apply(convert)\n",
      "  File \"/home/sonic/.conda/envs/RL_Env/lib/python3.7/site-packages/torch/nn/modules/module.py\", line 201, in _apply\n",
      "    module._apply(fn)\n",
      "  File \"/home/sonic/.conda/envs/RL_Env/lib/python3.7/site-packages/torch/nn/modules/module.py\", line 223, in _apply\n",
      "    param_applied = fn(param)\n",
      "  File \"/home/sonic/.conda/envs/RL_Env/lib/python3.7/site-packages/torch/nn/modules/module.py\", line 423, in convert\n",
      "    return t.to(device, dtype if t.is_floating_point() else None, non_blocking)\n",
      "  File \"/home/sonic/.conda/envs/RL_Env/lib/python3.7/site-packages/torch/cuda/__init__.py\", line 197, in _lazy_init\n",
      "    torch._C._cuda_init()\n",
      "RuntimeError: cuda runtime error (38) : no CUDA-capable device is detected at /opt/conda/conda-bld/pytorch_1579040055865/work/aten/src/THC/THCGeneral.cpp:50\n",
      "2021-01-23 07:44:09,732\tERROR worker.py:980 -- Possible unhandled error from worker: \u001b[36mray::Actor.__init__()\u001b[39m (pid=94219, ip=192.168.0.61)\n",
      "  File \"python/ray/_raylet.pyx\", line 463, in ray._raylet.execute_task\n",
      "  File \"python/ray/_raylet.pyx\", line 415, in ray._raylet.execute_task.function_executor\n",
      "  File \"<ipython-input-4-bb353c57f130>\", line 17, in __init__\n",
      "  File \"/home/sonic/.conda/envs/RL_Env/lib/python3.7/site-packages/torch/nn/modules/module.py\", line 425, in to\n",
      "    return self._apply(convert)\n",
      "  File \"/home/sonic/.conda/envs/RL_Env/lib/python3.7/site-packages/torch/nn/modules/module.py\", line 201, in _apply\n",
      "    module._apply(fn)\n",
      "  File \"/home/sonic/.conda/envs/RL_Env/lib/python3.7/site-packages/torch/nn/modules/module.py\", line 223, in _apply\n",
      "    param_applied = fn(param)\n",
      "  File \"/home/sonic/.conda/envs/RL_Env/lib/python3.7/site-packages/torch/nn/modules/module.py\", line 423, in convert\n",
      "    return t.to(device, dtype if t.is_floating_point() else None, non_blocking)\n",
      "  File \"/home/sonic/.conda/envs/RL_Env/lib/python3.7/site-packages/torch/cuda/__init__.py\", line 197, in _lazy_init\n",
      "    torch._C._cuda_init()\n",
      "RuntimeError: cuda runtime error (38) : no CUDA-capable device is detected at /opt/conda/conda-bld/pytorch_1579040055865/work/aten/src/THC/THCGeneral.cpp:50\n",
      "2021-01-23 07:44:09,735\tERROR worker.py:980 -- Possible unhandled error from worker: \u001b[36mray::Actor.__init__()\u001b[39m (pid=94296, ip=192.168.0.61)\n",
      "  File \"python/ray/_raylet.pyx\", line 463, in ray._raylet.execute_task\n",
      "  File \"python/ray/_raylet.pyx\", line 415, in ray._raylet.execute_task.function_executor\n",
      "  File \"<ipython-input-4-bb353c57f130>\", line 17, in __init__\n",
      "  File \"/home/sonic/.conda/envs/RL_Env/lib/python3.7/site-packages/torch/nn/modules/module.py\", line 425, in to\n",
      "    return self._apply(convert)\n",
      "  File \"/home/sonic/.conda/envs/RL_Env/lib/python3.7/site-packages/torch/nn/modules/module.py\", line 201, in _apply\n",
      "    module._apply(fn)\n",
      "  File \"/home/sonic/.conda/envs/RL_Env/lib/python3.7/site-packages/torch/nn/modules/module.py\", line 223, in _apply\n",
      "    param_applied = fn(param)\n",
      "  File \"/home/sonic/.conda/envs/RL_Env/lib/python3.7/site-packages/torch/nn/modules/module.py\", line 423, in convert\n",
      "    return t.to(device, dtype if t.is_floating_point() else None, non_blocking)\n",
      "  File \"/home/sonic/.conda/envs/RL_Env/lib/python3.7/site-packages/torch/cuda/__init__.py\", line 197, in _lazy_init\n",
      "    torch._C._cuda_init()\n",
      "RuntimeError: cuda runtime error (38) : no CUDA-capable device is detected at /opt/conda/conda-bld/pytorch_1579040055865/work/aten/src/THC/THCGeneral.cpp:50\n",
      "2021-01-23 07:44:09,737\tERROR worker.py:980 -- Possible unhandled error from worker: \u001b[36mray::Actor.explore()\u001b[39m (pid=94245, ip=192.168.0.61)\n",
      "  File \"python/ray/_raylet.pyx\", line 422, in ray._raylet.execute_task\n",
      "  File \"python/ray/_raylet.pyx\", line 456, in ray._raylet.execute_task\n",
      "  File \"python/ray/_raylet.pyx\", line 459, in ray._raylet.execute_task\n",
      "  File \"python/ray/_raylet.pyx\", line 463, in ray._raylet.execute_task\n",
      "  File \"python/ray/_raylet.pyx\", line 415, in ray._raylet.execute_task.function_executor\n",
      "  File \"<ipython-input-4-bb353c57f130>\", line 17, in __init__\n",
      "  File \"/home/sonic/.conda/envs/RL_Env/lib/python3.7/site-packages/torch/nn/modules/module.py\", line 425, in to\n",
      "    return self._apply(convert)\n",
      "  File \"/home/sonic/.conda/envs/RL_Env/lib/python3.7/site-packages/torch/nn/modules/module.py\", line 201, in _apply\n",
      "    module._apply(fn)\n",
      "  File \"/home/sonic/.conda/envs/RL_Env/lib/python3.7/site-packages/torch/nn/modules/module.py\", line 223, in _apply\n",
      "    param_applied = fn(param)\n",
      "  File \"/home/sonic/.conda/envs/RL_Env/lib/python3.7/site-packages/torch/nn/modules/module.py\", line 423, in convert\n",
      "    return t.to(device, dtype if t.is_floating_point() else None, non_blocking)\n",
      "  File \"/home/sonic/.conda/envs/RL_Env/lib/python3.7/site-packages/torch/cuda/__init__.py\", line 197, in _lazy_init\n",
      "    torch._C._cuda_init()\n",
      "RuntimeError: cuda runtime error (38) : no CUDA-capable device is detected at /opt/conda/conda-bld/pytorch_1579040055865/work/aten/src/THC/THCGeneral.cpp:50\n",
      "2021-01-23 07:44:09,739\tERROR worker.py:980 -- Possible unhandled error from worker: \u001b[36mray::Actor.__init__()\u001b[39m (pid=94214, ip=192.168.0.61)\n",
      "  File \"python/ray/_raylet.pyx\", line 463, in ray._raylet.execute_task\n",
      "  File \"python/ray/_raylet.pyx\", line 415, in ray._raylet.execute_task.function_executor\n",
      "  File \"<ipython-input-4-bb353c57f130>\", line 17, in __init__\n",
      "  File \"/home/sonic/.conda/envs/RL_Env/lib/python3.7/site-packages/torch/nn/modules/module.py\", line 425, in to\n",
      "    return self._apply(convert)\n",
      "  File \"/home/sonic/.conda/envs/RL_Env/lib/python3.7/site-packages/torch/nn/modules/module.py\", line 201, in _apply\n",
      "    module._apply(fn)\n",
      "  File \"/home/sonic/.conda/envs/RL_Env/lib/python3.7/site-packages/torch/nn/modules/module.py\", line 223, in _apply\n",
      "    param_applied = fn(param)\n",
      "  File \"/home/sonic/.conda/envs/RL_Env/lib/python3.7/site-packages/torch/nn/modules/module.py\", line 423, in convert\n",
      "    return t.to(device, dtype if t.is_floating_point() else None, non_blocking)\n",
      "  File \"/home/sonic/.conda/envs/RL_Env/lib/python3.7/site-packages/torch/cuda/__init__.py\", line 197, in _lazy_init\n",
      "    torch._C._cuda_init()\n",
      "RuntimeError: cuda runtime error (38) : no CUDA-capable device is detected at /opt/conda/conda-bld/pytorch_1579040055865/work/aten/src/THC/THCGeneral.cpp:50\n"
     ]
    },
    {
     "name": "stderr",
     "output_type": "stream",
     "text": [
      "2021-01-23 07:44:09,740\tERROR worker.py:980 -- Possible unhandled error from worker: \u001b[36mray::Actor.explore()\u001b[39m (pid=94263, ip=192.168.0.61)\n",
      "  File \"python/ray/_raylet.pyx\", line 422, in ray._raylet.execute_task\n",
      "  File \"python/ray/_raylet.pyx\", line 456, in ray._raylet.execute_task\n",
      "  File \"python/ray/_raylet.pyx\", line 459, in ray._raylet.execute_task\n",
      "  File \"python/ray/_raylet.pyx\", line 463, in ray._raylet.execute_task\n",
      "  File \"python/ray/_raylet.pyx\", line 415, in ray._raylet.execute_task.function_executor\n",
      "  File \"<ipython-input-4-bb353c57f130>\", line 17, in __init__\n",
      "  File \"/home/sonic/.conda/envs/RL_Env/lib/python3.7/site-packages/torch/nn/modules/module.py\", line 425, in to\n",
      "    return self._apply(convert)\n",
      "  File \"/home/sonic/.conda/envs/RL_Env/lib/python3.7/site-packages/torch/nn/modules/module.py\", line 201, in _apply\n",
      "    module._apply(fn)\n",
      "  File \"/home/sonic/.conda/envs/RL_Env/lib/python3.7/site-packages/torch/nn/modules/module.py\", line 223, in _apply\n",
      "    param_applied = fn(param)\n",
      "  File \"/home/sonic/.conda/envs/RL_Env/lib/python3.7/site-packages/torch/nn/modules/module.py\", line 423, in convert\n",
      "    return t.to(device, dtype if t.is_floating_point() else None, non_blocking)\n",
      "  File \"/home/sonic/.conda/envs/RL_Env/lib/python3.7/site-packages/torch/cuda/__init__.py\", line 197, in _lazy_init\n",
      "    torch._C._cuda_init()\n",
      "RuntimeError: cuda runtime error (38) : no CUDA-capable device is detected at /opt/conda/conda-bld/pytorch_1579040055865/work/aten/src/THC/THCGeneral.cpp:50\n",
      "2021-01-23 07:44:09,742\tERROR worker.py:980 -- Possible unhandled error from worker: \u001b[36mray::Actor.explore()\u001b[39m (pid=94219, ip=192.168.0.61)\n",
      "  File \"python/ray/_raylet.pyx\", line 422, in ray._raylet.execute_task\n",
      "  File \"python/ray/_raylet.pyx\", line 456, in ray._raylet.execute_task\n",
      "  File \"python/ray/_raylet.pyx\", line 459, in ray._raylet.execute_task\n",
      "  File \"python/ray/_raylet.pyx\", line 463, in ray._raylet.execute_task\n",
      "  File \"python/ray/_raylet.pyx\", line 415, in ray._raylet.execute_task.function_executor\n",
      "  File \"<ipython-input-4-bb353c57f130>\", line 17, in __init__\n",
      "  File \"/home/sonic/.conda/envs/RL_Env/lib/python3.7/site-packages/torch/nn/modules/module.py\", line 425, in to\n",
      "    return self._apply(convert)\n",
      "  File \"/home/sonic/.conda/envs/RL_Env/lib/python3.7/site-packages/torch/nn/modules/module.py\", line 201, in _apply\n",
      "    module._apply(fn)\n",
      "  File \"/home/sonic/.conda/envs/RL_Env/lib/python3.7/site-packages/torch/nn/modules/module.py\", line 223, in _apply\n",
      "    param_applied = fn(param)\n",
      "  File \"/home/sonic/.conda/envs/RL_Env/lib/python3.7/site-packages/torch/nn/modules/module.py\", line 423, in convert\n",
      "    return t.to(device, dtype if t.is_floating_point() else None, non_blocking)\n",
      "  File \"/home/sonic/.conda/envs/RL_Env/lib/python3.7/site-packages/torch/cuda/__init__.py\", line 197, in _lazy_init\n",
      "    torch._C._cuda_init()\n",
      "RuntimeError: cuda runtime error (38) : no CUDA-capable device is detected at /opt/conda/conda-bld/pytorch_1579040055865/work/aten/src/THC/THCGeneral.cpp:50\n",
      "2021-01-23 07:44:09,744\tERROR worker.py:980 -- Possible unhandled error from worker: \u001b[36mray::Actor.explore()\u001b[39m (pid=94296, ip=192.168.0.61)\n",
      "  File \"python/ray/_raylet.pyx\", line 422, in ray._raylet.execute_task\n",
      "  File \"python/ray/_raylet.pyx\", line 456, in ray._raylet.execute_task\n",
      "  File \"python/ray/_raylet.pyx\", line 459, in ray._raylet.execute_task\n",
      "  File \"python/ray/_raylet.pyx\", line 463, in ray._raylet.execute_task\n",
      "  File \"python/ray/_raylet.pyx\", line 415, in ray._raylet.execute_task.function_executor\n",
      "  File \"<ipython-input-4-bb353c57f130>\", line 17, in __init__\n",
      "  File \"/home/sonic/.conda/envs/RL_Env/lib/python3.7/site-packages/torch/nn/modules/module.py\", line 425, in to\n",
      "    return self._apply(convert)\n",
      "  File \"/home/sonic/.conda/envs/RL_Env/lib/python3.7/site-packages/torch/nn/modules/module.py\", line 201, in _apply\n",
      "    module._apply(fn)\n",
      "  File \"/home/sonic/.conda/envs/RL_Env/lib/python3.7/site-packages/torch/nn/modules/module.py\", line 223, in _apply\n",
      "    param_applied = fn(param)\n",
      "  File \"/home/sonic/.conda/envs/RL_Env/lib/python3.7/site-packages/torch/nn/modules/module.py\", line 423, in convert\n",
      "    return t.to(device, dtype if t.is_floating_point() else None, non_blocking)\n",
      "  File \"/home/sonic/.conda/envs/RL_Env/lib/python3.7/site-packages/torch/cuda/__init__.py\", line 197, in _lazy_init\n",
      "    torch._C._cuda_init()\n",
      "RuntimeError: cuda runtime error (38) : no CUDA-capable device is detected at /opt/conda/conda-bld/pytorch_1579040055865/work/aten/src/THC/THCGeneral.cpp:50\n",
      "2021-01-23 07:44:09,746\tERROR worker.py:980 -- Possible unhandled error from worker: \u001b[36mray::Actor.explore()\u001b[39m (pid=94214, ip=192.168.0.61)\n",
      "  File \"python/ray/_raylet.pyx\", line 422, in ray._raylet.execute_task\n",
      "  File \"python/ray/_raylet.pyx\", line 456, in ray._raylet.execute_task\n",
      "  File \"python/ray/_raylet.pyx\", line 459, in ray._raylet.execute_task\n",
      "  File \"python/ray/_raylet.pyx\", line 463, in ray._raylet.execute_task\n",
      "  File \"python/ray/_raylet.pyx\", line 415, in ray._raylet.execute_task.function_executor\n",
      "  File \"<ipython-input-4-bb353c57f130>\", line 17, in __init__\n",
      "  File \"/home/sonic/.conda/envs/RL_Env/lib/python3.7/site-packages/torch/nn/modules/module.py\", line 425, in to\n",
      "    return self._apply(convert)\n",
      "  File \"/home/sonic/.conda/envs/RL_Env/lib/python3.7/site-packages/torch/nn/modules/module.py\", line 201, in _apply\n",
      "    module._apply(fn)\n",
      "  File \"/home/sonic/.conda/envs/RL_Env/lib/python3.7/site-packages/torch/nn/modules/module.py\", line 223, in _apply\n",
      "    param_applied = fn(param)\n",
      "  File \"/home/sonic/.conda/envs/RL_Env/lib/python3.7/site-packages/torch/nn/modules/module.py\", line 423, in convert\n",
      "    return t.to(device, dtype if t.is_floating_point() else None, non_blocking)\n",
      "  File \"/home/sonic/.conda/envs/RL_Env/lib/python3.7/site-packages/torch/cuda/__init__.py\", line 197, in _lazy_init\n",
      "    torch._C._cuda_init()\n",
      "RuntimeError: cuda runtime error (38) : no CUDA-capable device is detected at /opt/conda/conda-bld/pytorch_1579040055865/work/aten/src/THC/THCGeneral.cpp:50\n",
      "2021-01-23 07:44:09,748\tERROR worker.py:980 -- Possible unhandled error from worker: \u001b[36mray::Actor.__init__()\u001b[39m (pid=94227, ip=192.168.0.61)\n",
      "  File \"python/ray/_raylet.pyx\", line 463, in ray._raylet.execute_task\n",
      "  File \"python/ray/_raylet.pyx\", line 415, in ray._raylet.execute_task.function_executor\n",
      "  File \"<ipython-input-4-bb353c57f130>\", line 17, in __init__\n",
      "  File \"/home/sonic/.conda/envs/RL_Env/lib/python3.7/site-packages/torch/nn/modules/module.py\", line 425, in to\n",
      "    return self._apply(convert)\n",
      "  File \"/home/sonic/.conda/envs/RL_Env/lib/python3.7/site-packages/torch/nn/modules/module.py\", line 201, in _apply\n",
      "    module._apply(fn)\n",
      "  File \"/home/sonic/.conda/envs/RL_Env/lib/python3.7/site-packages/torch/nn/modules/module.py\", line 223, in _apply\n",
      "    param_applied = fn(param)\n",
      "  File \"/home/sonic/.conda/envs/RL_Env/lib/python3.7/site-packages/torch/nn/modules/module.py\", line 423, in convert\n",
      "    return t.to(device, dtype if t.is_floating_point() else None, non_blocking)\n",
      "  File \"/home/sonic/.conda/envs/RL_Env/lib/python3.7/site-packages/torch/cuda/__init__.py\", line 197, in _lazy_init\n",
      "    torch._C._cuda_init()\n",
      "RuntimeError: cuda runtime error (38) : no CUDA-capable device is detected at /opt/conda/conda-bld/pytorch_1579040055865/work/aten/src/THC/THCGeneral.cpp:50\n",
      "2021-01-23 07:44:09,748\tERROR worker.py:980 -- Possible unhandled error from worker: \u001b[36mray::Actor.__init__()\u001b[39m (pid=94261, ip=192.168.0.61)\n",
      "  File \"python/ray/_raylet.pyx\", line 463, in ray._raylet.execute_task\n",
      "  File \"python/ray/_raylet.pyx\", line 415, in ray._raylet.execute_task.function_executor\n",
      "  File \"<ipython-input-4-bb353c57f130>\", line 17, in __init__\n",
      "  File \"/home/sonic/.conda/envs/RL_Env/lib/python3.7/site-packages/torch/nn/modules/module.py\", line 425, in to\n",
      "    return self._apply(convert)\n",
      "  File \"/home/sonic/.conda/envs/RL_Env/lib/python3.7/site-packages/torch/nn/modules/module.py\", line 201, in _apply\n",
      "    module._apply(fn)\n",
      "  File \"/home/sonic/.conda/envs/RL_Env/lib/python3.7/site-packages/torch/nn/modules/module.py\", line 223, in _apply\n",
      "    param_applied = fn(param)\n",
      "  File \"/home/sonic/.conda/envs/RL_Env/lib/python3.7/site-packages/torch/nn/modules/module.py\", line 423, in convert\n",
      "    return t.to(device, dtype if t.is_floating_point() else None, non_blocking)\n",
      "  File \"/home/sonic/.conda/envs/RL_Env/lib/python3.7/site-packages/torch/cuda/__init__.py\", line 197, in _lazy_init\n",
      "    torch._C._cuda_init()\n",
      "RuntimeError: cuda runtime error (38) : no CUDA-capable device is detected at /opt/conda/conda-bld/pytorch_1579040055865/work/aten/src/THC/THCGeneral.cpp:50\n"
     ]
    },
    {
     "name": "stderr",
     "output_type": "stream",
     "text": [
      "2021-01-23 07:44:09,750\tERROR worker.py:980 -- Possible unhandled error from worker: \u001b[36mray::Actor.__init__()\u001b[39m (pid=94230, ip=192.168.0.61)\n",
      "  File \"python/ray/_raylet.pyx\", line 463, in ray._raylet.execute_task\n",
      "  File \"python/ray/_raylet.pyx\", line 415, in ray._raylet.execute_task.function_executor\n",
      "  File \"<ipython-input-4-bb353c57f130>\", line 17, in __init__\n",
      "  File \"/home/sonic/.conda/envs/RL_Env/lib/python3.7/site-packages/torch/nn/modules/module.py\", line 425, in to\n",
      "    return self._apply(convert)\n",
      "  File \"/home/sonic/.conda/envs/RL_Env/lib/python3.7/site-packages/torch/nn/modules/module.py\", line 201, in _apply\n",
      "    module._apply(fn)\n",
      "  File \"/home/sonic/.conda/envs/RL_Env/lib/python3.7/site-packages/torch/nn/modules/module.py\", line 223, in _apply\n",
      "    param_applied = fn(param)\n",
      "  File \"/home/sonic/.conda/envs/RL_Env/lib/python3.7/site-packages/torch/nn/modules/module.py\", line 423, in convert\n",
      "    return t.to(device, dtype if t.is_floating_point() else None, non_blocking)\n",
      "  File \"/home/sonic/.conda/envs/RL_Env/lib/python3.7/site-packages/torch/cuda/__init__.py\", line 197, in _lazy_init\n",
      "    torch._C._cuda_init()\n",
      "RuntimeError: cuda runtime error (38) : no CUDA-capable device is detected at /opt/conda/conda-bld/pytorch_1579040055865/work/aten/src/THC/THCGeneral.cpp:50\n",
      "2021-01-23 07:44:09,752\tERROR worker.py:980 -- Possible unhandled error from worker: \u001b[36mray::Actor.explore()\u001b[39m (pid=94227, ip=192.168.0.61)\n",
      "  File \"python/ray/_raylet.pyx\", line 422, in ray._raylet.execute_task\n",
      "  File \"python/ray/_raylet.pyx\", line 456, in ray._raylet.execute_task\n",
      "  File \"python/ray/_raylet.pyx\", line 459, in ray._raylet.execute_task\n",
      "  File \"python/ray/_raylet.pyx\", line 463, in ray._raylet.execute_task\n",
      "  File \"python/ray/_raylet.pyx\", line 415, in ray._raylet.execute_task.function_executor\n",
      "  File \"<ipython-input-4-bb353c57f130>\", line 17, in __init__\n",
      "  File \"/home/sonic/.conda/envs/RL_Env/lib/python3.7/site-packages/torch/nn/modules/module.py\", line 425, in to\n",
      "    return self._apply(convert)\n",
      "  File \"/home/sonic/.conda/envs/RL_Env/lib/python3.7/site-packages/torch/nn/modules/module.py\", line 201, in _apply\n",
      "    module._apply(fn)\n",
      "  File \"/home/sonic/.conda/envs/RL_Env/lib/python3.7/site-packages/torch/nn/modules/module.py\", line 223, in _apply\n",
      "    param_applied = fn(param)\n",
      "  File \"/home/sonic/.conda/envs/RL_Env/lib/python3.7/site-packages/torch/nn/modules/module.py\", line 423, in convert\n",
      "    return t.to(device, dtype if t.is_floating_point() else None, non_blocking)\n",
      "  File \"/home/sonic/.conda/envs/RL_Env/lib/python3.7/site-packages/torch/cuda/__init__.py\", line 197, in _lazy_init\n",
      "    torch._C._cuda_init()\n",
      "RuntimeError: cuda runtime error (38) : no CUDA-capable device is detected at /opt/conda/conda-bld/pytorch_1579040055865/work/aten/src/THC/THCGeneral.cpp:50\n",
      "2021-01-23 07:44:09,753\tERROR worker.py:980 -- Possible unhandled error from worker: \u001b[36mray::Actor.explore()\u001b[39m (pid=94261, ip=192.168.0.61)\n",
      "  File \"python/ray/_raylet.pyx\", line 422, in ray._raylet.execute_task\n",
      "  File \"python/ray/_raylet.pyx\", line 456, in ray._raylet.execute_task\n",
      "  File \"python/ray/_raylet.pyx\", line 459, in ray._raylet.execute_task\n",
      "  File \"python/ray/_raylet.pyx\", line 463, in ray._raylet.execute_task\n",
      "  File \"python/ray/_raylet.pyx\", line 415, in ray._raylet.execute_task.function_executor\n",
      "  File \"<ipython-input-4-bb353c57f130>\", line 17, in __init__\n",
      "  File \"/home/sonic/.conda/envs/RL_Env/lib/python3.7/site-packages/torch/nn/modules/module.py\", line 425, in to\n",
      "    return self._apply(convert)\n",
      "  File \"/home/sonic/.conda/envs/RL_Env/lib/python3.7/site-packages/torch/nn/modules/module.py\", line 201, in _apply\n",
      "    module._apply(fn)\n",
      "  File \"/home/sonic/.conda/envs/RL_Env/lib/python3.7/site-packages/torch/nn/modules/module.py\", line 223, in _apply\n",
      "    param_applied = fn(param)\n",
      "  File \"/home/sonic/.conda/envs/RL_Env/lib/python3.7/site-packages/torch/nn/modules/module.py\", line 423, in convert\n",
      "    return t.to(device, dtype if t.is_floating_point() else None, non_blocking)\n",
      "  File \"/home/sonic/.conda/envs/RL_Env/lib/python3.7/site-packages/torch/cuda/__init__.py\", line 197, in _lazy_init\n",
      "    torch._C._cuda_init()\n",
      "RuntimeError: cuda runtime error (38) : no CUDA-capable device is detected at /opt/conda/conda-bld/pytorch_1579040055865/work/aten/src/THC/THCGeneral.cpp:50\n",
      "2021-01-23 07:44:09,755\tERROR worker.py:980 -- Possible unhandled error from worker: \u001b[36mray::Actor.explore()\u001b[39m (pid=94230, ip=192.168.0.61)\n",
      "  File \"python/ray/_raylet.pyx\", line 422, in ray._raylet.execute_task\n",
      "  File \"python/ray/_raylet.pyx\", line 456, in ray._raylet.execute_task\n",
      "  File \"python/ray/_raylet.pyx\", line 459, in ray._raylet.execute_task\n",
      "  File \"python/ray/_raylet.pyx\", line 463, in ray._raylet.execute_task\n",
      "  File \"python/ray/_raylet.pyx\", line 415, in ray._raylet.execute_task.function_executor\n",
      "  File \"<ipython-input-4-bb353c57f130>\", line 17, in __init__\n",
      "  File \"/home/sonic/.conda/envs/RL_Env/lib/python3.7/site-packages/torch/nn/modules/module.py\", line 425, in to\n",
      "    return self._apply(convert)\n",
      "  File \"/home/sonic/.conda/envs/RL_Env/lib/python3.7/site-packages/torch/nn/modules/module.py\", line 201, in _apply\n",
      "    module._apply(fn)\n",
      "  File \"/home/sonic/.conda/envs/RL_Env/lib/python3.7/site-packages/torch/nn/modules/module.py\", line 223, in _apply\n",
      "    param_applied = fn(param)\n",
      "  File \"/home/sonic/.conda/envs/RL_Env/lib/python3.7/site-packages/torch/nn/modules/module.py\", line 423, in convert\n",
      "    return t.to(device, dtype if t.is_floating_point() else None, non_blocking)\n",
      "  File \"/home/sonic/.conda/envs/RL_Env/lib/python3.7/site-packages/torch/cuda/__init__.py\", line 197, in _lazy_init\n",
      "    torch._C._cuda_init()\n",
      "RuntimeError: cuda runtime error (38) : no CUDA-capable device is detected at /opt/conda/conda-bld/pytorch_1579040055865/work/aten/src/THC/THCGeneral.cpp:50\n"
     ]
    }
   ],
   "source": [
    "num_actors = 16 # actor의 개수\n",
    "\n",
    "# num_actors 개수만큼 선언하고, explore 실행. actor라는 변수가 계속 중복이 되지만 실행은 잘 된다.\n",
    "for actor_idx in range(num_actors):\n",
    "    actor = Actor.remote(learner, actor_idx, hidden, device)\n",
    "    actor.explore.remote()"
   ]
  },
  {
   "cell_type": "code",
   "execution_count": null,
   "metadata": {},
   "outputs": [],
   "source": []
  },
  {
   "cell_type": "code",
   "execution_count": null,
   "metadata": {},
   "outputs": [],
   "source": []
  }
 ],
 "metadata": {
  "kernelspec": {
   "display_name": "Python 3",
   "language": "python",
   "name": "python3"
  },
  "language_info": {
   "codemirror_mode": {
    "name": "ipython",
    "version": 3
   },
   "file_extension": ".py",
   "mimetype": "text/x-python",
   "name": "python",
   "nbconvert_exporter": "python",
   "pygments_lexer": "ipython3",
   "version": "3.7.0"
  }
 },
 "nbformat": 4,
 "nbformat_minor": 4
}
